test_serialized_trades.json
[
  {
    "makerToken": "0xabcdefabcdefabcdefabcdefabcdefabcdefabcd",
    "takerToken": "0x1234567890123456789012345678901234567890",
    "makerAmount": "53",
    "takerAmount": "53",
    "maker": "0x6FEDd273B9aD26636De1d72178bA01b5b90efacA",
    "taker": "0x1dA076FF87c06a85740Fe7c25Fd0E5A4820c4a05",
    "sender": "0x0000000000000000000000000000000000000000",
    "feeRecipient": "0xfEDc000000000000000000000000000000000000",
    "pool": "0000000000000000000000000000000000000000000000000000000000000000",
    "expiration": 1729739184,
    "salt": "60359234022459116376763657822736912927529667485591768069604016375504390294384",
    "makerIsBuyer": false,
    "signature_type": "EIP-712",
    "buyer_v": 28,
    "buyer_r": "0xed52bb23d3f6843be29a5666f72093b00d888687f9d97b4c68bb7f5489616f0d",
    "buyer_s": "0x37b4b6565b416e42cf8781bbdbc801a228c4502cd4c01c76eac66fa724074c88",
    "seller_v": 27,
    "seller_r": "0x1cc2430877bace025ac4f6834dd3670e57d7347ef92e52365825d54583138ecf",
    "seller_s": "0xaf5ab897fa3dc5ef926e70b696eb58fc43ada24b8ae2a29746986d8f3d292542"
  },
  {
    "makerToken": "0xabcdefabcdefabcdefabcdefabcdefabcdefabcd",
    "takerToken": "0x1234567890123456789012345678901234567890",
    "makerAmount": "95",
    "takerAmount": "95",
    "maker": "0xDcE0Add3bb6C637181d3d2C25a834178Cf63Bcc5",
    "taker": "0x1dA076FF87c06a85740Fe7c25Fd0E5A4820c4a05",
    "sender": "0x0000000000000000000000000000000000000000",
    "feeRecipient": "0xfEDc000000000000000000000000000000000000",
    "pool": "0000000000000000000000000000000000000000000000000000000000000000",
    "expiration": 1729739184,
    "salt": "22004258266940295836234558389808025909396671167917328073563200015411263524672",
    "makerIsBuyer": false,
    "signature_type": "EIP-712",
    "buyer_v": 28,
    "buyer_r": "0xed52bb23d3f6843be29a5666f72093b00d888687f9d97b4c68bb7f5489616f0d",
    "buyer_s": "0x37b4b6565b416e42cf8781bbdbc801a228c4502cd4c01c76eac66fa724074c88",
    "seller_v": 28,
    "seller_r": "0x089c37e5155baab1bec258645cc9ae00751fe241f9fd138a3dd32713c1aa530d",
    "seller_s": "0xa036070b5dcb73d39a62c6d5c6848716cd1d115b5a2537e689b3b22e69f9f7e9"
  },
  {
    "makerToken": "0xabcdefabcdefabcdefabcdefabcdefabcdefabcd",
    "takerToken": "0x1234567890123456789012345678901234567890",
    "makerAmount": "18",
    "takerAmount": "18",
    "maker": "0xDcE0Add3bb6C637181d3d2C25a834178Cf63Bcc5",
    "taker": "0xC161720A782cbeaA8a8d059Bf73Cf0C7468E8b38",
    "sender": "0x0000000000000000000000000000000000000000",
    "feeRecipient": "0xfEDc000000000000000000000000000000000000",
    "pool": "0000000000000000000000000000000000000000000000000000000000000000",
    "expiration": 1729739184,
    "salt": "6043279660228324651187285341068949420997941419010489083274016951551022566877",
    "makerIsBuyer": false,
    "signature_type": "EIP-712",
    "buyer_v": 28,
    "buyer_r": "0x69e22e0e2370d21d4d1c7b0444068a4e94b1d4dee046a106003ed5713cecad0e",
    "buyer_s": "0x7083ad2ce1e04ea1009c90e985b0342c6ed7e716c7869fb7c8c3de327c090769",
    "seller_v": 28,
    "seller_r": "0x089c37e5155baab1bec258645cc9ae00751fe241f9fd138a3dd32713c1aa530d",
    "seller_s": "0xa036070b5dcb73d39a62c6d5c6848716cd1d115b5a2537e689b3b22e69f9f7e9"
  },
  {
    "makerToken": "0xabcdefabcdefabcdefabcdefabcdefabcdefabcd",
    "takerToken": "0x1234567890123456789012345678901234567890",
    "makerAmount": "72",
    "takerAmount": "216",
    "maker": "0x47801EDfD1B9ebcb168e8a6Dd331e28f4a26570C",
    "taker": "0xC161720A782cbeaA8a8d059Bf73Cf0C7468E8b38",
    "sender": "0x0000000000000000000000000000000000000000",
    "feeRecipient": "0xfEDc000000000000000000000000000000000000",
    "pool": "0000000000000000000000000000000000000000000000000000000000000000",
    "expiration": 1729739184,
    "salt": "61431099854713424414040867398740122398457420364920814885144758676786024848906",
    "makerIsBuyer": false,
    "signature_type": "EIP-712",
    "buyer_v": 28,
    "buyer_r": "0x69e22e0e2370d21d4d1c7b0444068a4e94b1d4dee046a106003ed5713cecad0e",
    "buyer_s": "0x7083ad2ce1e04ea1009c90e985b0342c6ed7e716c7869fb7c8c3de327c090769",
    "seller_v": 28,
    "seller_r": "0x7af9b65a1b483bd98686b61773bb57fb7c7f7be25997578f24593a61041153b2",
    "seller_s": "0x952dfa818bc089b451fe6de8e5f11660a8b1a0ecf8bca542cf846a48c7431e6b"
  },
  {
    "makerToken": "0xabcdefabcdefabcdefabcdefabcdefabcdefabcd",
    "takerToken": "0x1234567890123456789012345678901234567890",
    "makerAmount": "29",
    "takerAmount": "116",
    "maker": "0x14b929445357496d661C98E8E8dB0A776d91838f",
    "taker": "0xC161720A782cbeaA8a8d059Bf73Cf0C7468E8b38",
    "sender": "0x0000000000000000000000000000000000000000",
    "feeRecipient": "0xfEDc000000000000000000000000000000000000",
    "pool": "0000000000000000000000000000000000000000000000000000000000000000",
    "expiration": 1729739184,
    "salt": "39146225854790887368629841865969463853619524364722837047005674913536855394321",
    "makerIsBuyer": false,
    "signature_type": "EIP-712",
    "buyer_v": 28,
    "buyer_r": "0x69e22e0e2370d21d4d1c7b0444068a4e94b1d4dee046a106003ed5713cecad0e",
    "buyer_s": "0x7083ad2ce1e04ea1009c90e985b0342c6ed7e716c7869fb7c8c3de327c090769",
    "seller_v": 28,
    "seller_r": "0x7ed4267c5da1105ecbe173e0918aba6c55c6744c7644174b6a6d634a6bc1378c",
    "seller_s": "0x3774b813727c21adf8b23cbf488d025083bcdedb385eb58ab95c4f8a262cc1c6"
  },
  {
    "makerToken": "0x1234567890123456789012345678901234567890",
    "takerToken": "0xabcdefabcdefabcdefabcdefabcdefabcdefabcd",
    "makerAmount": "45",
    "takerAmount": "45",
    "maker": "0xd370f93915167E51a9BC660b622316ABDd1530FE",
    "taker": "0x4f2F6B43855a9F7309a239e9FfDb813473Cb4C64",
    "sender": "0x0000000000000000000000000000000000000000",
    "feeRecipient": "0xfEDc000000000000000000000000000000000000",
    "pool": "0000000000000000000000000000000000000000000000000000000000000000",
    "expiration": 1729739184,
    "salt": "70429788381121701868391960890035381912016902049818221008109921405722419209237",
    "makerIsBuyer": true,
    "signature_type": "EIP-712",
    "buyer_v": 28,
    "buyer_r": "0x0fc6ef6d535d864c18d1d66f68fb5c9a13d3db4f80d58c5cbd69099442ed221d",
    "buyer_s": "0x1022ea8d137135c9c576f575e36d86d9deb22c254fc95371ec4be4db5f6491aa",
    "seller_v": 27,
    "seller_r": "0x957cdad5fec00ac7ae2caa1578af83ce6663e7f9ceb53ffc2f52d5693fced348",
    "seller_s": "0xb708fc6846a2c7743baaa0c41a26be4eaa7856379a832a4192f89b02fb0e10c5"
  },
  {
    "makerToken": "0xabcdefabcdefabcdefabcdefabcdefabcdefabcd",
    "takerToken": "0x1234567890123456789012345678901234567890",
    "makerAmount": "56",
    "takerAmount": "224",
    "maker": "0x14b929445357496d661C98E8E8dB0A776d91838f",
    "taker": "0xD41A6Cb474d37F6a2b7453191F2093158738534f",
    "sender": "0x0000000000000000000000000000000000000000",
    "feeRecipient": "0xfEDc000000000000000000000000000000000000",
    "pool": "0000000000000000000000000000000000000000000000000000000000000000",
    "expiration": 1729739184,
    "salt": "61476822638178410702229636252958938127810022912476309469049890518259641680915",
    "makerIsBuyer": false,
    "signature_type": "EIP-712",
    "buyer_v": 27,
    "buyer_r": "0xfa4520c683132e1ef69070751b656cac9bed18632f7041b501be023c4e4757c6",
    "buyer_s": "0xe05dc031e31c3f4b44ece426a23831fd4bf591ece0e992511deba26ba2714c36",
    "seller_v": 28,
    "seller_r": "0x7ed4267c5da1105ecbe173e0918aba6c55c6744c7644174b6a6d634a6bc1378c",
    "seller_s": "0x3774b813727c21adf8b23cbf488d025083bcdedb385eb58ab95c4f8a262cc1c6"
  }
]
